<?xml version="1.0"?>
<robot xmlns:xacro="http://www.ros.org/wiki/xacro">
    

    

    <link name="base_bottom_link">
        <visual>
            <geometry>
                <box size="0.5 0.25 0.02"/>
            </geometry>
            <origin xyz="0.0 0.0 0.01" rpy="0.0 0.0 0.0"/>
            
            <material name="silver">
                <color rgba="0.75 0.75 0.75 1.0"/>
            </material>
        </visual>

        <collision>
            <geometry>
                <box size="0.5 0.25 0.02"/>
            </geometry>
            <origin xyz="0.0 0.0 0.01" rpy="0.0 0.0 0.0"/>
        </collision>
        <xacro:box m="1.0" l="0.5" w="0.25" h="0.02" xyz="0.0 0.0 0.01" rpy="0.0 0.0 0.0"/>
    </link>
    <link name="base_top_link">
        <visual>
            <geometry>
                <box size="0.5 0.25 0.02"/>
            </geometry>
            <origin xyz="0.0 0.0 0.0" rpy="0.0 0.0 0.0"/>
            
            <material name="silver">
                <color rgba="0.75 0.75 0.75 1.0"/>
            </material>
        </visual>
        <collision>
            <geometry>
                <box size="0.5 0.25 0.02"/>
            </geometry>
            <origin xyz="0.0 0.0 0.0" rpy="0.0 0.0 0.0"/>
        </collision>
        <xacro:box m="1.0" l="0.5" w ="0.25" h ="0.02"
            xyz ="0.0 0.0 0.01" rpy="0.0 0.0 0.0"/>
    </link>
    <joint name="base_bottom_base_top_joint" type="fixed">
        <parent link="base_bottom_link"/>
        <child link="base_top_link"/>
        <origin xyz="0.0 0.0 0.1" rpy="0.0 0.0 0.0"/>
    </joint>
    <link name="front_left_tire_link">
        <visual>
            <geometry>
                <cylinder radius="0.07" length="0.05"/>
            </geometry>
            <origin xyz="0.0 0.0 -0.025" rpy="0.0 0.0 0.0"/>                                                                                                                                                                                                                                                                                                                                            jjp;;;;;;;;;;;;;;;;;;;;;;;;;;;;;;;;;;;;;;;;;;;;;;;;;;;;;;;;;;;;;;;;;;;;;;;;;;;;;;;;;;;;;;;;;;;;;;;;;;;;;;;;;;;;;;;;;;;;;;;;;;;;;;;;;;;;;;;;;;;;;;;;;;;;;;;;;;;;;;;;;;;;;;;;;;;;;;;;;;;;;;;;;;;;;;;;;;;;;;;;;;;;;;;;;;;;;;;;;;;;;;;;;;;;;;;;;;;;;;;;;;;;;;;;;;;;;;;;;;;;;;;;;;;;;;;;;;;;;;;;;;;;;;;;;;;;;;;;;;;;;;;;;;;;;;;;;;;;;;;;;;;;;;;;;;;;;;;;;;;;;;;;;;;;;;;;;;;;;;;;;;;;;;;;;;;;;;;;;;;;;;;;;;;;;;;;;;;;;;;;;;;;;;;;;;;;;;;;;;;;;;;;;;;;;;;;;;;;;;;;;;;;;;;;;;;;;;;;;;;;;;;;;;;;;;;;;;;;;;;;;;;;;;;;;;;;;;;;;;;;;;;;;;;;;;;;;;;;;;;;;;;;;;;;;;;;;;;;;;;;;;;;;;;;;;;;;;;;;;;;;;;;;;;;;;;;;;;;;;;;;;;;;;;;;;;;;;;;;;;;;;;;;;;;;;;;;;;;;;;;;;;;;;;;;;;;;;;;;;;;;;;;;;;;;;;;;;;;;;;;;;;;;;;;;;;;;;;;;;;;;;;;;;;;;;;;;;;;;;;;;;;;;;;;;;;;;;;;;;;;;;;;;;;;;;;;;;;;;;;;;;;;;;;;;;;;;;;;;;;;;;;;;;;;;;;;;;;;;;;;;;;;;;;;;;;;;;;;;;;;;;;;;;;;;;;;;;;;;;;;;;;;;;;;;;;;;;;;;;;;;;;;;;;;;;;;;;;;;;;;;;;;;;;;;;;;;;;;;;;;;;;;;;;;;;;;;;;;;;;;;;;;;;;;;;;;;;;;;;;;;;;;;;;;;;;;;;;;;;;;;;;;;;;;;;;;;;;;;;;;;;;;;;;;;;;;;;;;;;;;;;;;;;;;;;;;;;;;;;;;;;;;;;;;;;;;;;;;;;;;;;;;;;;;;;;;;;;;;;;;;;;;;;;;;;;;;;;;;;;;;;;;;;;;;;;;;;;;;;;;;;;;;;;;;;;;;;;;;;;;;;;;;;;;;;;;;;;;;;;;;;;;;;;;;;;;;;;;;;;;;;;;;;;;;;;;;;;;;;;;;;;;;;;;;;;;;;;;;;;;;;;;;;;;;;;;;;;;;;;;;;;;;;;;;;;;;;;;;;;;;;;;;;;;;;;;;;;;;;;;;;;;;;;;;;;;;;;;;;;;;;;;;;;;;;;;;;;;;;;;;;;;;;;;;;;;;;;;;;;;;;;;;;;;;;;;;;;;;;;;;;;;;;;;;;;;;;;;;;;;;;;;;;;;;;;;;;;;;;;;;;;;;;;;;;;;;;;;;;;;;;;;;;;;;;;;;;;;;;;;;;;;ppp
            <material name="black">
                <color rgba="0.0 0.0 0.0 1.0"/>
            </material>
        </visual>
        <collision>
            <geometry>
                <cylinder radius="0.07" length="0.05"/>
            </geometry>
            <origin xyz="0.0 0.0 -0.025" rpy="0.0 0.0 0.0"/>  
        </collision>
        <xacro:cylinder m="1.0" r ="0.07" h ="0.05"
        xyz="0.0 0.0 -0.025" rpy="0.0 0.0 0.0"/>

    </link>

    <link name="front_right_tire_link">
        <visual>
            <geometry>
                <cylinder radius="0.07" length="0.05"/>
            </geometry>
            <origin xyz="0.0 0.0 0.025" rpy="0.0 0.0 0.0"/>
            <material name="black">
                <color rgba="0.0 0.0 0.0 1.0"/>
            </material>
        </visual>
        <collision>
            <geometry>
                <cylinder radius="0.07" length="0.05"/>
            </geometry>
            <origin xyz="0.0 0.0 0.025" rpy="0.0 0.0 0.0"/>
        </collision>

        <xacro:cylinder m="1.0" r ="0.07" h ="0.05"
        xyz="0.0 0.0 0.025" rpy="0.0 0.0 0.0"/>
    </link>
    
    <link name="back_right_tire_link">
        <visual>
            <geometry>
                <cylinder radius="0.07" length="0.05"/>
            </geometry>
            <origin xyz="0.0 0.0 0.025" rpy="0.0 0.0 0.0"/>
            <material name="black">
                <color rgba="0.0 0.0 0.0 1.0"/>
            </material>
        </visual>
        <collision>
            <geometry>
                <cylinder radius="0.07" length="0.05"/>
            </geometry>
            <origin xyz="0.0 0.0 0.025" rpy="0.0 0.0 0.0"/>
        </collision>

        <xacro:cylinder m="1.0" r ="0.07" h ="0.05"
        xyz="0.0 0.0 0.025" rpy="0.0 0.0 0.0"/>
    </link>

    <link name="back_left_tire_link">
        <visual>
            <geometry>
                <cylinder radius="0.07" length="0.05"/>
            </geometry>
            <origin xyz="0.0 0.0 -0.025" rpy="0.0 0.0 0.0"/>                                                                                                                                                                                                                                                                                                                                            jjp;;;;;;;;;;;;;;;;;;;;;;;;;;;;;;;;;;;;;;;;;;;;;;;;;;;;;;;;;;;;;;;;;;;;;;;;;;;;;;;;;;;;;;;;;;;;;;;;;;;;;;;;;;;;;;;;;;;;;;;;;;;;;;;;;;;;;;;;;;;;;;;;;;;;;;;;;;;;;;;;;;;;;;;;;;;;;;;;;;;;;;;;;;;;;;;;;;;;;;;;;;;;;;;;;;;;;;;;;;;;;;;;;;;;;;;;;;;;;;;;;;;;;;;;;;;;;;;;;;;;;;;;;;;;;;;;;;;;;;;;;;;;;;;;;;;;;;;;;;;;;;;;;;;;;;;;;;;;;;;;;;;;;;;;;;;;;;;;;;;;;;;;;;;;;;;;;;;;;;;;;;;;;;;;;;;;;;;;;;;;;;;;;;;;;;;;;;;;;;;;;;;;;;;;;;;;;;;;;;;;;;;;;;;;;;;;;;;;;;;;;;;;;;;;;;;;;;;;;;;;;;;;;;;;;;;;;;;;;;;;;;;;;;;;;;;;;;;;;;;;;;;;;;;;;;;;;;;;;;;;;;;;;;;;;;;;;;;;;;;;;;;;;;;;;;;;;;;;;;;;;;;;;;;;;;;;;;;;;;;;;;;;;;;;;;;;;;;;;;;;;;;;;;;;;;;;;;;;;;;;;;;;;;;;;;;;;;;;;;;;;;;;;;;;;;;;;;;;;;;;;;;;;;;;;;;;;;;;;;;;;;;;;;;;;;;;;;;;;;;;;;;;;;;;;;;;;;;;;;;;;;;;;;;;;;;;;;;;;;;;;;;;;;;;;;;;;;;;;;;;;;;;;;;;;;;;;;;;;;;;;;;;;;;;;;;;;;;;;;;;;;;;;;;;;;;;;;;;;;;;;;;;;;;;;;;;;;;;;;;;;;;;;;;;;;;;;;;;;;;;;;;;;;;;;;;;;;;;;;;;;;;;;;;;;;;;;;;;;;;;;;;;;;;;;;;;;;;;;;;;;;;;;;;;;;;;;;;;;;;;;;;;;;;;;;;;;;;;;;;;;;;;;;;;;;;;;;;;;;;;;;;;;;;;;;;;;;;;;;;;;;;;;;;;;;;;;;;;;;;;;;;;;;;;;;;;;;;;;;;;;;;;;;;;;;;;;;;;;;;;;;;;;;;;;;;;;;;;;;;;;;;;;;;;;;;;;;;;;;;;;;;;;;;;;;;;;;;;;;;;;;;;;;;;;;;;;;;;;;;;;;;;;;;;;;;;;;;;;;;;;;;;;;;;;;;;;;;;;;;;;;;;;;;;;;;;;;;;;;;;;;;;;;;;;;;;;;;;;;;;;;;;;;;;;;;;;;;;;;;;;;;;;;;;;;;;;;;;;;;;;;;;;;;;;;;;;;;;;;;;;;;;;;;;;;;;;;;;;;;;;;;;;;;;;;;;;;;;;;;;;;;;;;;;;;;;;;;;;;;;;;;;;;;;;;;;;;;;;;;;;;;;;;;;;;;;;;;;;;;;;;;;;;;;;;;;;;;;;;;;;;;;ppp
            <material name="black">
                <color rgba="0.0 0.0 0.0 1.0"/>
            </material>
        </visual>

        <collision>
            <geometry>
                <cylinder radius="0.07" length="0.05"/>
            </geometry>
            <origin xyz="0.0 0.0 -0.025" rpy="0.0 0.0 0.0"/>  
        </collision>
        <xacro:cylinder m="1.0" r ="0.07" h ="0.05"
        xyz="0.0 0.0 -0.025" rpy="0.0 0.0 0.0"/>
    </link>

    <joint name="base_bottom_back_left_tire_joint" type="continuous">
        <parent link="base_bottom_link"/>
        <child link="back_left_tire_link"/>
        <axis xyz="0 0 1"/>
        <origin xyz="-0.125 0.125 0.0" rpy="1.5708 0 0"/>
    </joint>

    <joint name="base_bottom_back_right_tire_joint" type="continuous">
        <parent link="base_bottom_link"/>
        <child link="back_right_tire_link"/>
        <axis xyz="0 0 1"/>
        <origin xyz="-0.125 -0.125 0.0" rpy="1.5708 0 0"/>
    </joint>

    <joint name="base_bottom_front_right_tire_joint" type="continuous">
        <parent link="base_bottom_link"/>
        <child link="front_right_tire_link"/>
        <axis xyz="0 0 1"/>
        <origin xyz="0.125 -0.125 0.0" rpy="1.5708 0 0"/>
    </joint>

    <joint name="base_bottom_front_left_tire_joint" type="continuous">
        <parent link="base_bottom_link"/>
        <child link="front_left_tire_link"/>
        <axis xyz="0 0 1"/>
        <origin xyz="0.125 0.125 0.0" rpy="1.5708 0 0"/>
    </joint>
    
</robot>
